Workbook

Sheet Guía
A1: Potencial preflop de las 169 manos iniciales de Texas Hold'em
A3: Qué es: para cada mano, la probabilidad de terminar (al llegar al river) con cada categoría de mano.
A4: Método: enumeración EXACTA. Para cada mano se recorren los C(50,5) = 2.118.760 tableros posibles y se cuenta en cuántos sale cada categoría. Sin azar ni simulación.
A5: Categoría = mejor mano de 5 cartas entre tus 2 y las 5 del tablero (7 cartas).
A6: Las categorías de 'Probabilidades' son excluyentes y suman 100 %. Las columnas acumuladas ('o mejor') suman las categorías superiores.
A7: 'Mejora al tablero': el tablero solo (5 cartas) tiene una categoría; aquí cuenta cuando tus 2 cartas suben esa categoría. Es una medida aproximada de cuánto aportan tus cartas (no detecta mejoras dentro de la misma categoría, p. ej. un color más alto).
A8: Los palos son simétricos: se calculó una mano representativa por tipo (pareja, suited, offsuit). 'Combos' = cuántas manos concretas de las 1.326 hay de ese tipo (6, 4 o 12).
A9: Validación: el promedio ponderado por combos coincide EXACTO con el conteo clásico de las 133.784.560 manos de 7 cartas (hoja 'Validación').
A11: Ojo: potencial NO es equity. Una escalera baja pierde contra un color o una escalera mayor. Esta hoja mide versatilidad, no probabilidad de ganar.
A12: Mapas: arriba de la diagonal = suited, abajo = offsuit, diagonal = parejas.
A13: Hojas: Conteos (datos crudos, en azul) → Probabilidades (fórmulas) → Mapas y Validación.

Sheet Conteos
A1: Mano | B1: Tipo | C1: Combos | D1: Tableros | E1: Carta alta | F1: Pareja | G1: Doble pareja | H1: Trío | I1: Escalera | J1: Color | K1: Full house | L1: Póker | M1: Escalera de color | N1: Mejora al tablero
A2: AA | B2: Pareja | C2: 6 | D2: 2118760 | E2: 0 | F2: 762300 | G2: 840456 | H2: 249458 | I2: 25816 | J2: 41562 | K2: 181104 | L2: 17848 | M2: 216 | N2: 2006938
A3: AKo | B3: Offsuit | C3: 12 | D3: 2118760 | E3: 417780 | F3: 965568 | G3: 480080 | H3: 93808 | I3: 69954 | J3: 41562 | K3: 47124 | L3: 2668 | M3: 216 | N3: 1084878
A4: AKs | B4: Suited | C4: 4 | D4: 2118760 | E4: 386130 | F4: 916776 | G4: 469092 | H4: 92004 | I4: 65508 | J4: 138296 | K4: 47124 | L4: 2668 | M4: 1162 | N4: 1157513
A5: AQo | B5: Offsuit | C5: 12 | D5: 2118760 | E5: 412830 | F5: 962560 | G5: 480080 | H5: 93808 | I5: 77912 | J5: 41518 | K5: 47124 | L5: 2668 | M5: 260 | N5: 1091589
A6: AQs | B6: Suited | C6: 4 | D6: 2118760 | E6: 381555 | F6: 913920 | G6: 469092 | H6: 92004 | I6: 72939 | J6: 138252 | K6: 47124 | L6: 2668 | M6: 1206 | N6: 1163687
A7: AJo | B7: Offsuit | C7: 12 | D7: 2118760 | E7: 407880 | F7: 959552 | G7: 480080 | H7: 93808 | I7: 85870 | J7: 41474 | K7: 47124 | L7: 2668 | M7: 304 | N7: 1098300
A8: AJs | B8: Suited | C8: 4 | D8: 2118760 | E8: 376980 | F8: 911064 | G8: 469092 | H8: 92004 | I8: 80370 | J8: 138208 | K8: 47124 | L8: 2668 | M8: 1250 | N8: 1169861
A9: ATo | B9: Offsuit | C9: 12 | D9: 2118760 | E9: 402930 | F9: 956544 | G9: 480080 | H9: 93808 | I9: 93828 | J9: 41430 | K9: 47124 | L9: 2668 | M9: 348 | N9: 1105011
A10: ATs | B10: Suited | C10: 4 | D10: 2118760 | E10: 372405 | F10: 908208 | G10: 469092 | H10: 92004 | I10: 87801 | J10: 138164 | K10: 47124 | L10: 2668 | M10: 1294 | N10: 1176035
A11: A9o | B11: Offsuit | C11: 12 | D11: 2118760 | E11: 418770 | F11: 974592 | G11: 482790 | H11: 94380 | I11: 56658 | J11: 41431 | K11: 47124 | L11: 2668 | M11: 347 | N11: 1079536
A12: A9s | B12: Suited | C12: 4 | D12: 2118760 | E12: 387045 | F12: 925344 | G12: 471735 | H12: 92565 | I12: 52821 | J12: 139155 | K12: 47124 | L12: 2668 | M12: 303 | N12: 1152395
A13: A8o | B13: Offsuit | C13: 12 | D13: 2118760 | E13: 413820 | F13: 971584 | G13: 482790 | H13: 94380 | I13: 64616 | J13: 41431 | K13: 47124 | L13: 2668 | M13: 347 | N13: 1085998
... A170: 22 | B170: Pareja | C170: 6 | D170: 2118760 | E170: 0 | F170: 762300 | G170: 840456 | H170: 249458 | I170: 25816 | J170: 41562 | K170: 181104 | L170: 17848 | M170: 216 | N170: 2006938

Sheet Probabilidades
A1: Mano | B1: Tipo | C1: Combos | D1: Carta alta | E1: Pareja | F1: Doble pareja | G1: Trío | H1: Escalera | I1: Color | J1: Full house | K1: Póker | L1: Escalera de color | M1: Escalera o mejor | N1: Color o mejor | O1: Trío o mejor | P1: Mejora al tablero
A2: =Conteos!A2 -> AA | B2: =Conteos!B2 -> Pareja | C2: =Conteos!C2 -> 6 | D2: =Conteos!E2/Conteos!$D2 -> 0 | E2: =Conteos!F2/Conteos!$D2 -> 0.35978591 | F2: =Conteos!G2/Conteos!$D2 -> 0.39667353 | G2: =Conteos!H2/Conteos!$D2 -> 0.11773773 | H2: =Conteos!I2/Conteos!$D2 -> 0.012184485 | I2: =Conteos!J2/Conteos!$D2 -> 0.019616191 | J2: =Conteos!K2/Conteos!$D2 -> 0.085476411 | K2: =Conteos!L2/Conteos!$D2 -> 0.008423795 | L2: =Conteos!M2/Conteos!$D2 -> 0.00010194642 | M2: =SUM(H2:L2) -> 0.12580283 | N2: =SUM(I2:L2) -> 0.11361834 | O2: =SUM(G2:L2) -> 0.24354056 | P2: =Conteos!N2/Conteos!D2 -> 0.9472229
A3: =Conteos!A3 -> AKo | B3: =Conteos!B3 -> Offsuit | C3: =Conteos!C3 -> 12 | D3: =Conteos!E3/Conteos!$D3 -> 0.19718137 | E3: =Conteos!F3/Conteos!$D3 -> 0.45572316 | F3: =Conteos!G3/Conteos!$D3 -> 0.22658536 | G3: =Conteos!H3/Conteos!$D3 -> 0.044274953 | H3: =Conteos!I3/Conteos!$D3 -> 0.033016481 | I3: =Conteos!J3/Conteos!$D3 -> 0.019616191 | J3: =Conteos!K3/Conteos!$D3 -> 0.022241311 | K3: =Conteos!L3/Conteos!$D3 -> 0.0012592271 | L3: =Conteos!M3/Conteos!$D3 -> 0.00010194642 | M3: =SUM(H3:L3) -> 0.076235156 | N3: =SUM(I3:L3) -> 0.043218675 | O3: =SUM(G3:L3) -> 0.12051011 | P3: =Conteos!N3/Conteos!D3 -> 0.5120344
A4: =Conteos!A4 -> AKs | B4: =Conteos!B4 -> Suited | C4: =Conteos!C4 -> 4 | D4: =Conteos!E4/Conteos!$D4 -> 0.18224339 | E4: =Conteos!F4/Conteos!$D4 -> 0.43269459 | F4: =Conteos!G4/Conteos!$D4 -> 0.22139931 | G4: =Conteos!H4/Conteos!$D4 -> 0.043423512 | H4: =Conteos!I4/Conteos!$D4 -> 0.030918084 | I4: =Conteos!J4/Conteos!$D4 -> 0.06527214 | J4: =Conteos!K4/Conteos!$D4 -> 0.022241311 | K4: =Conteos!L4/Conteos!$D4 -> 0.0012592271 | L4: =Conteos!M4/Conteos!$D4 -> 0.00054843399 | M4: =SUM(H4:L4) -> 0.1202392 | N4: =SUM(I4:L4) -> 0.089321112 | O4: =SUM(G4:L4) -> 0.16366271 | P4: =Conteos!N4/Conteos!D4 -> 0.54631624
A5: =Conteos!A5 -> AQo | B5: =Conteos!B5 -> Offsuit | C5: =Conteos!C5 -> 12 | D5: =Conteos!E5/Conteos!$D5 -> 0.1948451 | E5: =Conteos!F5/Conteos!$D5 -> 0.45430346 | F5: =Conteos!G5/Conteos!$D5 -> 0.22658536 | G5: =Conteos!H5/Conteos!$D5 -> 0.044274953 | H5: =Conteos!I5/Conteos!$D5 -> 0.036772452 | I5: =Conteos!J5/Conteos!$D5 -> 0.019595424 | J5: =Conteos!K5/Conteos!$D5 -> 0.022241311 | K5: =Conteos!L5/Conteos!$D5 -> 0.0012592271 | L5: =Conteos!M5/Conteos!$D5 -> 0.00012271329 | M5: =SUM(H5:L5) -> 0.079991127 | N5: =SUM(I5:L5) -> 0.043218675 | O5: =SUM(G5:L5) -> 0.12426608 | P5: =Conteos!N5/Conteos!D5 -> 0.51520182
A6: =Conteos!A6 -> AQs | B6: =Conteos!B6 -> Suited | C6: =Conteos!C6 -> 4 | D6: =Conteos!E6/Conteos!$D6 -> 0.18008411 | E6: =Conteos!F6/Conteos!$D6 -> 0.43134664 | F6: =Conteos!G6/Conteos!$D6 -> 0.22139931 | G6: =Conteos!H6/Conteos!$D6 -> 0.043423512 | H6: =Conteos!I6/Conteos!$D6 -> 0.034425324 | I6: =Conteos!J6/Conteos!$D6 -> 0.065251373 | J6: =Conteos!K6/Conteos!$D6 -> 0.022241311 | K6: =Conteos!L6/Conteos!$D6 -> 0.0012592271 | L6: =Conteos!M6/Conteos!$D6 -> 0.00056920085 | M6: =SUM(H6:L6) -> 0.12374644 | N6: =SUM(I6:L6) -> 0.089321112 | O6: =SUM(G6:L6) -> 0.16716995 | P6: =Conteos!N6/Conteos!D6 -> 0.54923021
A7: =Conteos!A7 -> AJo | B7: =Conteos!B7 -> Offsuit | C7: =Conteos!C7 -> 12 | D7: =Conteos!E7/Conteos!$D7 -> 0.19250883 | E7: =Conteos!F7/Conteos!$D7 -> 0.45288376 | F7: =Conteos!G7/Conteos!$D7 -> 0.22658536 | G7: =Conteos!H7/Conteos!$D7 -> 0.044274953 | H7: =Conteos!I7/Conteos!$D7 -> 0.040528422 | I7: =Conteos!J7/Conteos!$D7 -> 0.019574657 | J7: =Conteos!K7/Conteos!$D7 -> 0.022241311 | K7: =Conteos!L7/Conteos!$D7 -> 0.0012592271 | L7: =Conteos!M7/Conteos!$D7 -> 0.00014348015 | M7: =SUM(H7:L7) -> 0.083747097 | N7: =SUM(I7:L7) -> 0.043218675 | O7: =SUM(G7:L7) -> 0.12802205 | P7: =Conteos!N7/Conteos!D7 -> 0.51836923
A8: =Conteos!A8 -> AJs | B8: =Conteos!B8 -> Suited | C8: =Conteos!C8 -> 4 | D8: =Conteos!E8/Conteos!$D8 -> 0.17792482 | E8: =Conteos!F8/Conteos!$D8 -> 0.42999868 | F8: =Conteos!G8/Conteos!$D8 -> 0.22139931 | G8: =Conteos!H8/Conteos!$D8 -> 0.043423512 | H8: =Conteos!I8/Conteos!$D8 -> 0.037932564 | I8: =Conteos!J8/Conteos!$D8 -> 0.065230607 | J8: =Conteos!K8/Conteos!$D8 -> 0.022241311 | K8: =Conteos!L8/Conteos!$D8 -> 0.0012592271 | L8: =Conteos!M8/Conteos!$D8 -> 0.00058996772 | M8: =SUM(H8:L8) -> 0.12725368 | N8: =SUM(I8:L8) -> 0.089321112 | O8: =SUM(G8:L8) -> 0.17067719 | P8: =Conteos!N8/Conteos!D8 -> 0.55214418
A9: =Conteos!A9 -> ATo | B9: =Conteos!B9 -> Offsuit | C9: =Conteos!C9 -> 12 | D9: =Conteos!E9/Conteos!$D9 -> 0.19017255 | E9: =Conteos!F9/Conteos!$D9 -> 0.45146406 | F9: =Conteos!G9/Conteos!$D9 -> 0.22658536 | G9: =Conteos!H9/Conteos!$D9 -> 0.044274953 | H9: =Conteos!I9/Conteos!$D9 -> 0.044284393 | I9: =Conteos!J9/Conteos!$D9 -> 0.01955389 | J9: =Conteos!K9/Conteos!$D9 -> 0.022241311 | K9: =Conteos!L9/Conteos!$D9 -> 0.0012592271 | L9: =Conteos!M9/Conteos!$D9 -> 0.00016424701 | M9: =SUM(H9:L9) -> 0.087503068 | N9: =SUM(I9:L9) -> 0.043218675 | O9: =SUM(G9:L9) -> 0.13177802 | P9: =Conteos!N9/Conteos!D9 -> 0.52153665
A10: =Conteos!A10 -> ATs | B10: =Conteos!B10 -> Suited | C10: =Conteos!C10 -> 4 | D10: =Conteos!E10/Conteos!$D10 -> 0.17576554 | E10: =Conteos!F10/Conteos!$D10 -> 0.42865072 | F10: =Conteos!G10/Conteos!$D10 -> 0.22139931 | G10: =Conteos!H10/Conteos!$D10 -> 0.043423512 | H10: =Conteos!I10/Conteos!$D10 -> 0.041439804 | I10: =Conteos!J10/Conteos!$D10 -> 0.06520984 | J10: =Conteos!K10/Conteos!$D10 -> 0.022241311 | K10: =Conteos!L10/Conteos!$D10 -> 0.0012592271 | L10: =Conteos!M10/Conteos!$D10 -> 0.00061073458 | M10: =SUM(H10:L10) -> 0.13076092 | N10: =SUM(I10:L10) -> 0.089321112 | O10: =SUM(G10:L10) -> 0.17418443 | P10: =Conteos!N10/Conteos!D10 -> 0.55505815
A11: =Conteos!A11 -> A9o | B11: =Conteos!B11 -> Offsuit | C11: =Conteos!C11 -> 12 | D11: =Conteos!E11/Conteos!$D11 -> 0.19764862 | E11: =Conteos!F11/Conteos!$D11 -> 0.45998225 | F11: =Conteos!G11/Conteos!$D11 -> 0.22786441 | G11: =Conteos!H11/Conteos!$D11 -> 0.044544923 | H11: =Conteos!I11/Conteos!$D11 -> 0.026741113 | I11: =Conteos!J11/Conteos!$D11 -> 0.019554362 | J11: =Conteos!K11/Conteos!$D11 -> 0.022241311 | K11: =Conteos!L11/Conteos!$D11 -> 0.0012592271 | L11: =Conteos!M11/Conteos!$D11 -> 0.00016377504 | M11: =SUM(H11:L11) -> 0.069959788 | N11: =SUM(I11:L11) -> 0.043218675 | O11: =SUM(G11:L11) -> 0.11450471 | P11: =Conteos!N11/Conteos!D11 -> 0.50951311
A12: =Conteos!A12 -> A9s | B12: =Conteos!B12 -> Suited | C12: =Conteos!C12 -> 4 | D12: =Conteos!E12/Conteos!$D12 -> 0.18267524 | E12: =Conteos!F12/Conteos!$D12 -> 0.43673847 | F12: =Conteos!G12/Conteos!$D12 -> 0.22264674 | G12: =Conteos!H12/Conteos!$D12 -> 0.043688289 | H12: =Conteos!I12/Conteos!$D12 -> 0.024930148 | I12: =Conteos!J12/Conteos!$D12 -> 0.065677566 | J12: =Conteos!K12/Conteos!$D12 -> 0.022241311 | K12: =Conteos!L12/Conteos!$D12 -> 0.0012592271 | L12: =Conteos!M12/Conteos!$D12 -> 0.00014300817 | M12: =SUM(H12:L12) -> 0.11425126 | N12: =SUM(I12:L12) -> 0.089321112 | O12: =SUM(G12:L12) -> 0.15793955 | P12: =Conteos!N12/Conteos!D12 -> 0.54390068
A13: =Conteos!A13 -> A8o | B13: =Conteos!B13 -> Offsuit | C13: =Conteos!C13 -> 12 | D13: =Conteos!E13/Conteos!$D13 -> 0.19531235 | E13: =Conteos!F13/Conteos!$D13 -> 0.45856256 | F13: =Conteos!G13/Conteos!$D13 -> 0.22786441 | G13: =Conteos!H13/Conteos!$D13 -> 0.044544923 | H13: =Conteos!I13/Conteos!$D13 -> 0.030497083 | I13: =Conteos!J13/Conteos!$D13 -> 0.019554362 | J13: =Conteos!K13/Conteos!$D13 -> 0.022241311 | K13: =Conteos!L13/Conteos!$D13 -> 0.0012592271 | L13: =Conteos!M13/Conteos!$D13 -> 0.00016377504 | M13: =SUM(H13:L13) -> 0.073715758 | N13: =SUM(I13:L13) -> 0.043218675 | O13: =SUM(G13:L13) -> 0.11826068 | P13: =Conteos!N13/Conteos!D13 -> 0.51256301
... A170: =Conteos!A170 -> 22 | B170: =Conteos!B170 -> Pareja | C170: =Conteos!C170 -> 6 | D170: =Conteos!E170/Conteos!$D170 -> 0 | E170: =Conteos!F170/Conteos!$D170 -> 0.35978591 | F170: =Conteos!G170/Conteos!$D170 -> 0.39667353 | G170: =Conteos!H170/Conteos!$D170 -> 0.11773773 | H170: =Conteos!I170/Conteos!$D170 -> 0.012184485 | I170: =Conteos!J170/Conteos!$D170 -> 0.019616191 | J170: =Conteos!K170/Conteos!$D170 -> 0.085476411 | K170: =Conteos!L170/Conteos!$D170 -> 0.008423795 | L170: =Conteos!M170/Conteos!$D170 -> 0.00010194642 | M170: =SUM(H170:L170) -> 0.12580283 | N170: =SUM(I170:L170) -> 0.11361834 | O170: =SUM(G170:L170) -> 0.24354056 | P170: =Conteos!N170/Conteos!D170 -> 0.9472229

Sheet Mapas
A1: Escalera o mejor (probabilidad por el river)
B2: A | C2: K | D2: Q | E2: J | F2: T | G2: 9 | H2: 8 | I2: 7 | J2: 6 | K2: 5 | L2: 4 | M2: 3 | N2: 2
A3: A | B3: =INDEX(Probabilidades!$M$2:$M$170,MATCH("AA",Probabilidades!$A$2:$A$170,0)) -> 0.12580283 | C3: =INDEX(Probabilidades!$M$2:$M$170,MATCH("AKs",Probabilidades!$A$2:$A$170,0)) -> 0.1202392 | D3: =INDEX(Probabilidades!$M$2:$M$170,MATCH("AQs",Probabilidades!$A$2:$A$170,0)) -> 0.12374644 | E3: =INDEX(Probabilidades!$M$2:$M$170,MATCH("AJs",Probabilidades!$A$2:$A$170,0)) -> 0.12725368 | F3: =INDEX(Probabilidades!$M$2:$M$170,MATCH("ATs",Probabilidades!$A$2:$A$170,0)) -> 0.13076092 | G3: =INDEX(Probabilidades!$M$2:$M$170,MATCH("A9s",Probabilidades!$A$2:$A$170,0)) -> 0.11425126 | H3: =INDEX(Probabilidades!$M$2:$M$170,MATCH("A8s",Probabilidades!$A$2:$A$170,0)) -> 0.1177585 | I3: =INDEX(Probabilidades!$M$2:$M$170,MATCH("A7s",Probabilidades!$A$2:$A$170,0)) -> 0.1177585 | J3: =INDEX(Probabilidades!$M$2:$M$170,MATCH("A6s",Probabilidades!$A$2:$A$170,0)) -> 0.11425126 | K3: =INDEX(Probabilidades!$M$2:$M$170,MATCH("A5s",Probabilidades!$A$2:$A$170,0)) -> 0.13076092 | L3: =INDEX(Probabilidades!$M$2:$M$170,MATCH("A4s",Probabilidades!$A$2:$A$170,0)) -> 0.12725368 | M3: =INDEX(Probabilidades!$M$2:$M$170,MATCH("A3s",Probabilidades!$A$2:$A$170,0)) -> 0.12374644 | N3: =INDEX(Probabilidades!$M$2:$M$170,MATCH("A2s",Probabilidades!$A$2:$A$170,0)) -> 0.1202392
A4: K | B4: =INDEX(Probabilidades!$M$2:$M$170,MATCH("AKo",Probabilidades!$A$2:$A$170,0)) -> 0.076235156 | C4: =INDEX(Probabilidades!$M$2:$M$170,MATCH("KK",Probabilidades!$A$2:$A$170,0)) -> 0.12580283 | D4: =INDEX(Probabilidades!$M$2:$M$170,MATCH("KQs",Probabilidades!$A$2:$A$170,0)) -> 0.136317 | E4: =INDEX(Probabilidades!$M$2:$M$170,MATCH("KJs",Probabilidades!$A$2:$A$170,0)) -> 0.13982424 | F4: =INDEX(Probabilidades!$M$2:$M$170,MATCH("KTs",Probabilidades!$A$2:$A$170,0)) -> 0.14333148 | G4: =INDEX(Probabilidades!$M$2:$M$170,MATCH("K9s",Probabilidades!$A$2:$A$170,0)) -> 0.12682182 | H4: =INDEX(Probabilidades!$M$2:$M$170,MATCH("K8s",Probabilidades!$A$2:$A$170,0)) -> 0.11425126 | I4: =INDEX(Probabilidades!$M$2:$M$170,MATCH("K7s",Probabilidades!$A$2:$A$170,0)) -> 0.1177585 | J4: =INDEX(Probabilidades!$M$2:$M$170,MATCH("K6s",Probabilidades!$A$2:$A$170,0)) -> 0.1177585 | K4: =INDEX(Probabilidades!$M$2:$M$170,MATCH("K5s",Probabilidades!$A$2:$A$170,0)) -> 0.11819036 | L4: =INDEX(Probabilidades!$M$2:$M$170,MATCH("K4s",Probabilidades!$A$2:$A$170,0)) -> 0.11468312 | M4: =INDEX(Probabilidades!$M$2:$M$170,MATCH("K3s",Probabilidades!$A$2:$A$170,0)) -> 0.11117588 | N4: =INDEX(Probabilidades!$M$2:$M$170,MATCH("K2s",Probabilidades!$A$2:$A$170,0)) -> 0.10766864
A5: Q | B5: =INDEX(Probabilidades!$M$2:$M$170,MATCH("AQo",Probabilidades!$A$2:$A$170,0)) -> 0.079991127 | C5: =INDEX(Probabilidades!$M$2:$M$170,MATCH("KQo",Probabilidades!$A$2:$A$170,0)) -> 0.093311182 | D5: =INDEX(Probabilidades!$M$2:$M$170,MATCH("QQ",Probabilidades!$A$2:$A$170,0)) -> 0.1295588 | E5: =INDEX(Probabilidades!$M$2:$M$170,MATCH("QJs",Probabilidades!$A$2:$A$170,0)) -> 0.15590204 | F5: =INDEX(Probabilidades!$M$2:$M$170,MATCH("QTs",Probabilidades!$A$2:$A$170,0)) -> 0.15940928 | G5: =INDEX(Probabilidades!$M$2:$M$170,MATCH("Q9s",Probabilidades!$A$2:$A$170,0)) -> 0.14289962 | H5: =INDEX(Probabilidades!$M$2:$M$170,MATCH("Q8s",Probabilidades!$A$2:$A$170,0)) -> 0.13032906 | I5: =INDEX(Probabilidades!$M$2:$M$170,MATCH("Q7s",Probabilidades!$A$2:$A$170,0)) -> 0.1177585 | J5: =INDEX(Probabilidades!$M$2:$M$170,MATCH("Q6s",Probabilidades!$A$2:$A$170,0)) -> 0.12126574 | K5: =INDEX(Probabilidades!$M$2:$M$170,MATCH("Q5s",Probabilidades!$A$2:$A$170,0)) -> 0.1216976 | L5: =INDEX(Probabilidades!$M$2:$M$170,MATCH("Q4s",Probabilidades!$A$2:$A$170,0)) -> 0.11819036 | M5: =INDEX(Probabilidades!$M$2:$M$170,MATCH("Q3s",Probabilidades!$A$2:$A$170,0)) -> 0.11468312 | N5: =INDEX(Probabilidades!$M$2:$M$170,MATCH("Q2s",Probabilidades!$A$2:$A$170,0)) -> 0.11117588
A6: J | B6: =INDEX(Probabilidades!$M$2:$M$170,MATCH("AJo",Probabilidades!$A$2:$A$170,0)) -> 0.083747097 | C6: =INDEX(Probabilidades!$M$2:$M$170,MATCH("KJo",Probabilidades!$A$2:$A$170,0)) -> 0.097067152 | D6: =INDEX(Probabilidades!$M$2:$M$170,MATCH("QJo",Probabilidades!$A$2:$A$170,0)) -> 0.11414318 | E6: =INDEX(Probabilidades!$M$2:$M$170,MATCH("JJ",Probabilidades!$A$2:$A$170,0)) -> 0.13331477 | F6: =INDEX(Probabilidades!$M$2:$M$170,MATCH("JTs",Probabilidades!$A$2:$A$170,0)) -> 0.17548708 | G6: =INDEX(Probabilidades!$M$2:$M$170,MATCH("J9s",Probabilidades!$A$2:$A$170,0)) -> 0.15897742 | H6: =INDEX(Probabilidades!$M$2:$M$170,MATCH("J8s",Probabilidades!$A$2:$A$170,0)) -> 0.14640686 | I6: =INDEX(Probabilidades!$M$2:$M$170,MATCH("J7s",Probabilidades!$A$2:$A$170,0)) -> 0.1338363 | J6: =INDEX(Probabilidades!$M$2:$M$170,MATCH("J6s",Probabilidades!$A$2:$A$170,0)) -> 0.12126574 | K6: =INDEX(Probabilidades!$M$2:$M$170,MATCH("J5s",Probabilidades!$A$2:$A$170,0)) -> 0.12520484 | L6: =INDEX(Probabilidades!$M$2:$M$170,MATCH("J4s",Probabilidades!$A$2:$A$170,0)) -> 0.1216976 | M6: =INDEX(Probabilidades!$M$2:$M$170,MATCH("J3s",Probabilidades!$A$2:$A$170,0)) -> 0.11819036 | N6: =INDEX(Probabilidades!$M$2:$M$170,MATCH("J2s",Probabilidades!$A$2:$A$170,0)) -> 0.11468312
A7: T | B7: =INDEX(Probabilidades!$M$2:$M$170,MATCH("ATo",Probabilidades!$A$2:$A$170,0)) -> 0.087503068 | C7: =INDEX(Probabilidades!$M$2:$M$170,MATCH("KTo",Probabilidades!$A$2:$A$170,0)) -> 0.10082312 | D7: =INDEX(Probabilidades!$M$2:$M$170,MATCH("QTo",Probabilidades!$A$2:$A$170,0)) -> 0.11789915 | E7: =INDEX(Probabilidades!$M$2:$M$170,MATCH("JTo",Probabilidades!$A$2:$A$170,0)) -> 0.13497517 | F7: =INDEX(Probabilidades!$M$2:$M$170,MATCH("TT",Probabilidades!$A$2:$A$170,0)) -> 0.13707074 | G7: =INDEX(Probabilidades!$M$2:$M$170,MATCH("T9s",Probabilidades!$A$2:$A$170,0)) -> 0.17505522 | H7: =INDEX(Probabilidades!$M$2:$M$170,MATCH("T8s",Probabilidades!$A$2:$A$170,0)) -> 0.16248466 | I7: =INDEX(Probabilidades!$M$2:$M$170,MATCH("T7s",Probabilidades!$A$2:$A$170,0)) -> 0.1499141 | J7: =INDEX(Probabilidades!$M$2:$M$170,MATCH("T6s",Probabilidades!$A$2:$A$170,0)) -> 0.13734354 | K7: =INDEX(Probabilidades!$M$2:$M$170,MATCH("T5s",Probabilidades!$A$2:$A$170,0)) -> 0.12520484 | L7: =INDEX(Probabilidades!$M$2:$M$170,MATCH("T4s",Probabilidades!$A$2:$A$170,0)) -> 0.12520484 | M7: =INDEX(Probabilidades!$M$2:$M$170,MATCH("T3s",Probabilidades!$A$2:$A$170,0)) -> 0.1216976 | N7: =INDEX(Probabilidades!$M$2:$M$170,MATCH("T2s",Probabilidades!$A$2:$A$170,0)) -> 0.11819036
A8: 9 | B8: =INDEX(Probabilidades!$M$2:$M$170,MATCH("A9o",Probabilidades!$A$2:$A$170,0)) -> 0.069959788 | C8: =INDEX(Probabilidades!$M$2:$M$170,MATCH("K9o",Probabilidades!$A$2:$A$170,0)) -> 0.083279843 | D8: =INDEX(Probabilidades!$M$2:$M$170,MATCH("Q9o",Probabilidades!$A$2:$A$170,0)) -> 0.10035587 | E8: =INDEX(Probabilidades!$M$2:$M$170,MATCH("J9o",Probabilidades!$A$2:$A$170,0)) -> 0.11743189 | F8: =INDEX(Probabilidades!$M$2:$M$170,MATCH("T9o",Probabilidades!$A$2:$A$170,0)) -> 0.13450792 | G8: =INDEX(Probabilidades!$M$2:$M$170,MATCH("99",Probabilidades!$A$2:$A$170,0)) -> 0.13660349 | H8: =INDEX(Probabilidades!$M$2:$M$170,MATCH("98s",Probabilidades!$A$2:$A$170,0)) -> 0.17462336 | I8: =INDEX(Probabilidades!$M$2:$M$170,MATCH("97s",Probabilidades!$A$2:$A$170,0)) -> 0.1620528 | J8: =INDEX(Probabilidades!$M$2:$M$170,MATCH("96s",Probabilidades!$A$2:$A$170,0)) -> 0.14948224 | K8: =INDEX(Probabilidades!$M$2:$M$170,MATCH("95s",Probabilidades!$A$2:$A$170,0)) -> 0.13734354 | L8: =INDEX(Probabilidades!$M$2:$M$170,MATCH("94s",Probabilidades!$A$2:$A$170,0)) -> 0.12126574 | M8: =INDEX(Probabilidades!$M$2:$M$170,MATCH("93s",Probabilidades!$A$2:$A$170,0)) -> 0.12126574 | N8: =INDEX(Probabilidades!$M$2:$M$170,MATCH("92s",Probabilidades!$A$2:$A$170,0)) -> 0.1177585
A9: 8 | B9: =INDEX(Probabilidades!$M$2:$M$170,MATCH("A8o",Probabilidades!$A$2:$A$170,0)) -> 0.073715758 | C9: =INDEX(Probabilidades!$M$2:$M$170,MATCH("K8o",Probabilidades!$A$2:$A$170,0)) -> 0.069959788 | D9: =INDEX(Probabilidades!$M$2:$M$170,MATCH("Q8o",Probabilidades!$A$2:$A$170,0)) -> 0.087035813 | E9: =INDEX(Probabilidades!$M$2:$M$170,MATCH("J8o",Probabilidades!$A$2:$A$170,0)) -> 0.10411184 | F9: =INDEX(Probabilidades!$M$2:$M$170,MATCH("T8o",Probabilidades!$A$2:$A$170,0)) -> 0.12118786 | G9: =INDEX(Probabilidades!$M$2:$M$170,MATCH("98o",Probabilidades!$A$2:$A$170,0)) -> 0.13404067 | H9: =INDEX(Probabilidades!$M$2:$M$170,MATCH("88",Probabilidades!$A$2:$A$170,0)) -> 0.13660349 | I9: =INDEX(Probabilidades!$M$2:$M$170,MATCH("87s",Probabilidades!$A$2:$A$170,0)) -> 0.17462336 | J9: =INDEX(Probabilidades!$M$2:$M$170,MATCH("86s",Probabilidades!$A$2:$A$170,0)) -> 0.1620528 | K9: =INDEX(Probabilidades!$M$2:$M$170,MATCH("85s",Probabilidades!$A$2:$A$170,0)) -> 0.1499141 | L9: =INDEX(Probabilidades!$M$2:$M$170,MATCH("84s",Probabilidades!$A$2:$A$170,0)) -> 0.1338363 | M9: =INDEX(Probabilidades!$M$2:$M$170,MATCH("83s",Probabilidades!$A$2:$A$170,0)) -> 0.1177585 | N9: =INDEX(Probabilidades!$M$2:$M$170,MATCH("82s",Probabilidades!$A$2:$A$170,0)) -> 0.1177585
A10: 7 | B10: =INDEX(Probabilidades!$M$2:$M$170,MATCH("A7o",Probabilidades!$A$2:$A$170,0)) -> 0.073715758 | C10: =INDEX(Probabilidades!$M$2:$M$170,MATCH("K7o",Probabilidades!$A$2:$A$170,0)) -> 0.073715758 | D10: =INDEX(Probabilidades!$M$2:$M$170,MATCH("Q7o",Probabilidades!$A$2:$A$170,0)) -> 0.073715758 | E10: =INDEX(Probabilidades!$M$2:$M$170,MATCH("J7o",Probabilidades!$A$2:$A$170,0)) -> 0.090791784 | F10: =INDEX(Probabilidades!$M$2:$M$170,MATCH("T7o",Probabilidades!$A$2:$A$170,0)) -> 0.10786781 | G10: =INDEX(Probabilidades!$M$2:$M$170,MATCH("97o",Probabilidades!$A$2:$A$170,0)) -> 0.12072061 | H10: =INDEX(Probabilidades!$M$2:$M$170,MATCH("87o",Probabilidades!$A$2:$A$170,0)) -> 0.13404067 | I10: =INDEX(Probabilidades!$M$2:$M$170,MATCH("77",Probabilidades!$A$2:$A$170,0)) -> 0.13660349 | J10: =INDEX(Probabilidades!$M$2:$M$170,MATCH("76s",Probabilidades!$A$2:$A$170,0)) -> 0.17462336 | K10: =INDEX(Probabilidades!$M$2:$M$170,MATCH("75s",Probabilidades!$A$2:$A$170,0)) -> 0.16248466 | L10: =INDEX(Probabilidades!$M$2:$M$170,MATCH("74s",Probabilidades!$A$2:$A$170,0)) -> 0.14640686 | M10: =INDEX(Probabilidades!$M$2:$M$170,MATCH("73s",Probabilidades!$A$2:$A$170,0)) -> 0.13032906 | N10: =INDEX(Probabilidades!$M$2:$M$170,MATCH("72s",Probabilidades!$A$2:$A$170,0)) -> 0.11425126
A11: 6 | B11: =INDEX(Probabilidades!$M$2:$M$170,MATCH("A6o",Probabilidades!$A$2:$A$170,0)) -> 0.069959788 | C11: =INDEX(Probabilidades!$M$2:$M$170,MATCH("K6o",Probabilidades!$A$2:$A$170,0)) -> 0.073715758 | D11: =INDEX(Probabilidades!$M$2:$M$170,MATCH("Q6o",Probabilidades!$A$2:$A$170,0)) -> 0.077471729 | E11: =INDEX(Probabilidades!$M$2:$M$170,MATCH("J6o",Probabilidades!$A$2:$A$170,0)) -> 0.077471729 | F11: =INDEX(Probabilidades!$M$2:$M$170,MATCH("T6o",Probabilidades!$A$2:$A$170,0)) -> 0.094547754 | G11: =INDEX(Probabilidades!$M$2:$M$170,MATCH("96o",Probabilidades!$A$2:$A$170,0)) -> 0.10740056 | H11: =INDEX(Probabilidades!$M$2:$M$170,MATCH("86o",Probabilidades!$A$2:$A$170,0)) -> 0.12072061 | I11: =INDEX(Probabilidades!$M$2:$M$170,MATCH("76o",Probabilidades!$A$2:$A$170,0)) -> 0.13404067 | J11: =INDEX(Probabilidades!$M$2:$M$170,MATCH("66",Probabilidades!$A$2:$A$170,0)) -> 0.13660349 | K11: =INDEX(Probabilidades!$M$2:$M$170,MATCH("65s",Probabilidades!$A$2:$A$170,0)) -> 0.17505522 | L11: =INDEX(Probabilidades!$M$2:$M$170,MATCH("64s",Probabilidades!$A$2:$A$170,0)) -> 0.15897742 | M11: =INDEX(Probabilidades!$M$2:$M$170,MATCH("63s",Probabilidades!$A$2:$A$170,0)) -> 0.14289962 | N11: =INDEX(Probabilidades!$M$2:$M$170,MATCH("62s",Probabilidades!$A$2:$A$170,0)) -> 0.12682182
A12: 5 | B12: =INDEX(Probabilidades!$M$2:$M$170,MATCH("A5o",Probabilidades!$A$2:$A$170,0)) -> 0.087503068 | C12: =INDEX(Probabilidades!$M$2:$M$170,MATCH("K5o",Probabilidades!$A$2:$A$170,0)) -> 0.074183013 | D12: =INDEX(Probabilidades!$M$2:$M$170,MATCH("Q5o",Probabilidades!$A$2:$A$170,0)) -> 0.077938983 | E12: =INDEX(Probabilidades!$M$2:$M$170,MATCH("J5o",Probabilidades!$A$2:$A$170,0)) -> 0.081694954 | F12: =INDEX(Probabilidades!$M$2:$M$170,MATCH("T5o",Probabilidades!$A$2:$A$170,0)) -> 0.081694954 | G12: =INDEX(Probabilidades!$M$2:$M$170,MATCH("95o",Probabilidades!$A$2:$A$170,0)) -> 0.094547754 | H12: =INDEX(Probabilidades!$M$2:$M$170,MATCH("85o",Probabilidades!$A$2:$A$170,0)) -> 0.10786781 | I12: =INDEX(Probabilidades!$M$2:$M$170,MATCH("75o",Probabilidades!$A$2:$A$170,0)) -> 0.12118786 | J12: =INDEX(Probabilidades!$M$2:$M$170,MATCH("65o",Probabilidades!$A$2:$A$170,0)) -> 0.13450792 | K12: =INDEX(Probabilidades!$M$2:$M$170,MATCH("55",Probabilidades!$A$2:$A$170,0)) -> 0.13707074 | L12: =INDEX(Probabilidades!$M$2:$M$170,MATCH("54s",Probabilidades!$A$2:$A$170,0)) -> 0.17548708 | M12: =INDEX(Probabilidades!$M$2:$M$170,MATCH("53s",Probabilidades!$A$2:$A$170,0)) -> 0.15940928 | N12: =INDEX(Probabilidades!$M$2:$M$170,MATCH("52s",Probabilidades!$A$2:$A$170,0)) -> 0.14333148
A13: 4 | B13: =INDEX(Probabilidades!$M$2:$M$170,MATCH("A4o",Probabilidades!$A$2:$A$170,0)) -> 0.083747097 | C13: =INDEX(Probabilidades!$M$2:$M$170,MATCH("K4o",Probabilidades!$A$2:$A$170,0)) -> 0.070427042 | D13: =INDEX(Probabilidades!$M$2:$M$170,MATCH("Q4o",Probabilidades!$A$2:$A$170,0)) -> 0.074183013 | E13: =INDEX(Probabilidades!$M$2:$M$170,MATCH("J4o",Probabilidades!$A$2:$A$170,0)) -> 0.077938983 | F13: =INDEX(Probabilidades!$M$2:$M$170,MATCH("T4o",Probabilidades!$A$2:$A$170,0)) -> 0.081694954 | G13: =INDEX(Probabilidades!$M$2:$M$170,MATCH("94o",Probabilidades!$A$2:$A$170,0)) -> 0.077471729 | H13: =INDEX(Probabilidades!$M$2:$M$170,MATCH("84o",Probabilidades!$A$2:$A$170,0)) -> 0.090791784 | I13: =INDEX(Probabilidades!$M$2:$M$170,MATCH("74o",Probabilidades!$A$2:$A$170,0)) -> 0.10411184 | J13: =INDEX(Probabilidades!$M$2:$M$170,MATCH("64o",Probabilidades!$A$2:$A$170,0)) -> 0.11743189 | K13: =INDEX(Probabilidades!$M$2:$M$170,MATCH("54o",Probabilidades!$A$2:$A$170,0)) -> 0.13497517 | L13: =INDEX(Probabilidades!$M$2:$M$170,MATCH("44",Probabilidades!$A$2:$A$170,0)) -> 0.13331477 | M13: =INDEX(Probabilidades!$M$2:$M$170,MATCH("43s",Probabilidades!$A$2:$A$170,0)) -> 0.15590204 | N13: =INDEX(Probabilidades!$M$2:$M$170,MATCH("42s",Probabilidades!$A$2:$A$170,0)) -> 0.13982424
A14: 3 | B14: =INDEX(Probabilidades!$M$2:$M$170,MATCH("A3o",Probabilidades!$A$2:$A$170,0)) -> 0.079991127 | C14: =INDEX(Probabilidades!$M$2:$M$170,MATCH("K3o",Probabilidades!$A$2:$A$170,0)) -> 0.066671072 | D14: =INDEX(Probabilidades!$M$2:$M$170,MATCH("Q3o",Probabilidades!$A$2:$A$170,0)) -> 0.070427042 | E14: =INDEX(Probabilidades!$M$2:$M$170,MATCH("J3o",Probabilidades!$A$2:$A$170,0)) -> 0.074183013 | F14: =INDEX(Probabilidades!$M$2:$M$170,MATCH("T3o",Probabilidades!$A$2:$A$170,0)) -> 0.077938983 | G14: =INDEX(Probabilidades!$M$2:$M$170,MATCH("93o",Probabilidades!$A$2:$A$170,0)) -> 0.077471729 | H14: =INDEX(Probabilidades!$M$2:$M$170,MATCH("83o",Probabilidades!$A$2:$A$170,0)) -> 0.073715758 | I14: =INDEX(Probabilidades!$M$2:$M$170,MATCH("73o",Probabilidades!$A$2:$A$170,0)) -> 0.087035813 | J14: =INDEX(Probabilidades!$M$2:$M$170,MATCH("63o",Probabilidades!$A$2:$A$170,0)) -> 0.10035587 | K14: =INDEX(Probabilidades!$M$2:$M$170,MATCH("53o",Probabilidades!$A$2:$A$170,0)) -> 0.11789915 | L14: =INDEX(Probabilidades!$M$2:$M$170,MATCH("43o",Probabilidades!$A$2:$A$170,0)) -> 0.11414318 | M14: =INDEX(Probabilidades!$M$2:$M$170,MATCH("33",Probabilidades!$A$2:$A$170,0)) -> 0.1295588 | N14: =INDEX(Probabilidades!$M$2:$M$170,MATCH("32s",Probabilidades!$A$2:$A$170,0)) -> 0.136317
A15: 2 | B15: =INDEX(Probabilidades!$M$2:$M$170,MATCH("A2o",Probabilidades!$A$2:$A$170,0)) -> 0.076235156 | C15: =INDEX(Probabilidades!$M$2:$M$170,MATCH("K2o",Probabilidades!$A$2:$A$170,0)) -> 0.062915101 | D15: =INDEX(Probabilidades!$M$2:$M$170,MATCH("Q2o",Probabilidades!$A$2:$A$170,0)) -> 0.066671072 | E15: =INDEX(Probabilidades!$M$2:$M$170,MATCH("J2o",Probabilidades!$A$2:$A$170,0)) -> 0.070427042 | F15: =INDEX(Probabilidades!$M$2:$M$170,MATCH("T2o",Probabilidades!$A$2:$A$170,0)) -> 0.074183013 | G15: =INDEX(Probabilidades!$M$2:$M$170,MATCH("92o",Probabilidades!$A$2:$A$170,0)) -> 0.073715758 | H15: =INDEX(Probabilidades!$M$2:$M$170,MATCH("82o",Probabilidades!$A$2:$A$170,0)) -> 0.073715758 | I15: =INDEX(Probabilidades!$M$2:$M$170,MATCH("72o",Probabilidades!$A$2:$A$170,0)) -> 0.069959788 | J15: =INDEX(Probabilidades!$M$2:$M$170,MATCH("62o",Probabilidades!$A$2:$A$170,0)) -> 0.083279843 | K15: =INDEX(Probabilidades!$M$2:$M$170,MATCH("52o",Probabilidades!$A$2:$A$170,0)) -> 0.10082312 | L15: =INDEX(Probabilidades!$M$2:$M$170,MATCH("42o",Probabilidades!$A$2:$A$170,0)) -> 0.097067152 | M15: =INDEX(Probabilidades!$M$2:$M$170,MATCH("32o",Probabilidades!$A$2:$A$170,0)) -> 0.093311182 | N15: =INDEX(Probabilidades!$M$2:$M$170,MATCH("22",Probabilidades!$A$2:$A$170,0)) -> 0.12580283
A18: Color o mejor (color, full, póker o escalera de color)
B19: A | C19: K | D19: Q | E19: J | F19: T | G19: 9 | H19: 8 | I19: 7 | J19: 6 | K19: 5 | L19: 4 | M19: 3 | N19: 2
A20: A | B20: =INDEX(Probabilidades!$N$2:$N$170,MATCH("AA",Probabilidades!$A$2:$A$170,0)) -> 0.11361834 | C20: =INDEX(Probabilidades!$N$2:$N$170,MATCH("AKs",Probabilidades!$A$2:$A$170,0)) -> 0.089321112 | D20: =INDEX(Probabilidades!$N$2:$N$170,MATCH("AQs",Probabilidades!$A$2:$A$170,0)) -> 0.089321112 | E20: =INDEX(Probabilidades!$N$2:$N$170,MATCH("AJs",Probabilidades!$A$2:$A$170,0)) -> 0.089321112 | F20: =INDEX(Probabilidades!$N$2:$N$170,MATCH("ATs",Probabilidades!$A$2:$A$170,0)) -> 0.089321112 | G20: =INDEX(Probabilidades!$N$2:$N$170,MATCH("A9s",Probabilidades!$A$2:$A$170,0)) -> 0.089321112 | H20: =INDEX(Probabilidades!$N$2:$N$170,MATCH("A8s",Probabilidades!$A$2:$A$170,0)) -> 0.089321112 | I20: =INDEX(Probabilidades!$N$2:$N$170,MATCH("A7s",Probabilidades!$A$2:$A$170,0)) -> 0.089321112 | J20: =INDEX(Probabilidades!$N$2:$N$170,MATCH("A6s",Probabilidades!$A$2:$A$170,0)) -> 0.089321112 | K20: =INDEX(Probabilidades!$N$2:$N$170,MATCH("A5s",Probabilidades!$A$2:$A$170,0)) -> 0.089321112 | L20: =INDEX(Probabilidades!$N$2:$N$170,MATCH("A4s",Probabilidades!$A$2:$A$170,0)) -> 0.089321112 | M20: =INDEX(Probabilidades!$N$2:$N$170,MATCH("A3s",Probabilidades!$A$2:$A$170,0)) -> 0.089321112 | N20: =INDEX(Probabilidades!$N$2:$N$170,MATCH("A2s",Probabilidades!$A$2:$A$170,0)) -> 0.089321112
A21: K | B21: =INDEX(Probabilidades!$N$2:$N$170,MATCH("AKo",Probabilidades!$A$2:$A$170,0)) -> 0.043218675 | C21: =INDEX(Probabilidades!$N$2:$N$170,MATCH("KK",Probabilidades!$A$2:$A$170,0)) -> 0.11361834 | D21: =INDEX(Probabilidades!$N$2:$N$170,MATCH("KQs",Probabilidades!$A$2:$A$170,0)) -> 0.089321112 | E21: =INDEX(Probabilidades!$N$2:$N$170,MATCH("KJs",Probabilidades!$A$2:$A$170,0)) -> 0.089321112 | F21: =INDEX(Probabilidades!$N$2:$N$170,MATCH("KTs",Probabilidades!$A$2:$A$170,0)) -> 0.089321112 | G21: =INDEX(Probabilidades!$N$2:$N$170,MATCH("K9s",Probabilidades!$A$2:$A$170,0)) -> 0.089321112 | H21: =INDEX(Probabilidades!$N$2:$N$170,MATCH("K8s",Probabilidades!$A$2:$A$170,0)) -> 0.089321112 | I21: =INDEX(Probabilidades!$N$2:$N$170,MATCH("K7s",Probabilidades!$A$2:$A$170,0)) -> 0.089321112 | J21: =INDEX(Probabilidades!$N$2:$N$170,MATCH("K6s",Probabilidades!$A$2:$A$170,0)) -> 0.089321112 | K21: =INDEX(Probabilidades!$N$2:$N$170,MATCH("K5s",Probabilidades!$A$2:$A$170,0)) -> 0.089321112 | L21: =INDEX(Probabilidades!$N$2:$N$170,MATCH("K4s",Probabilidades!$A$2:$A$170,0)) -> 0.089321112 | M21: =INDEX(Probabilidades!$N$2:$N$170,MATCH("K3s",Probabilidades!$A$2:$A$170,0)) -> 0.089321112 | N21: =INDEX(Probabilidades!$N$2:$N$170,MATCH("K2s",Probabilidades!$A$2:$A$170,0)) -> 0.089321112
A22: Q | B22: =INDEX(Probabilidades!$N$2:$N$170,MATCH("AQo",Probabilidades!$A$2:$A$170,0)) -> 0.043218675 | C22: =INDEX(Probabilidades!$N$2:$N$170,MATCH("KQo",Probabilidades!$A$2:$A$170,0)) -> 0.043218675 | D22: =INDEX(Probabilidades!$N$2:$N$170,MATCH("QQ",Probabilidades!$A$2:$A$170,0)) -> 0.11361834 | E22: =INDEX(Probabilidades!$N$2:$N$170,MATCH("QJs",Probabilidades!$A$2:$A$170,0)) -> 0.089321112 | F22: =INDEX(Probabilidades!$N$2:$N$170,MATCH("QTs",Probabilidades!$A$2:$A$170,0)) -> 0.089321112 | G22: =INDEX(Probabilidades!$N$2:$N$170,MATCH("Q9s",Probabilidades!$A$2:$A$170,0)) -> 0.089321112 | H22: =INDEX(Probabilidades!$N$2:$N$170,MATCH("Q8s",Probabilidades!$A$2:$A$170,0)) -> 0.089321112 | I22: =INDEX(Probabilidades!$N$2:$N$170,MATCH("Q7s",Probabilidades!$A$2:$A$170,0)) -> 0.089321112 | J22: =INDEX(Probabilidades!$N$2:$N$170,MATCH("Q6s",Probabilidades!$A$2:$A$170,0)) -> 0.089321112 | K22: =INDEX(Probabilidades!$N$2:$N$170,MATCH("Q5s",Probabilidades!$A$2:$A$170,0)) -> 0.089321112 | L22: =INDEX(Probabilidades!$N$2:$N$170,MATCH("Q4s",Probabilidades!$A$2:$A$170,0)) -> 0.089321112 | M22: =INDEX(Probabilidades!$N$2:$N$170,MATCH("Q3s",Probabilidades!$A$2:$A$170,0)) -> 0.089321112 | N22: =INDEX(Probabilidades!$N$2:$N$170,MATCH("Q2s",Probabilidades!$A$2:$A$170,0)) -> 0.089321112
A23: J | B23: =INDEX(Probabilidades!$N$2:$N$170,MATCH("AJo",Probabilidades!$A$2:$A$170,0)) -> 0.043218675 | C23: =INDEX(Probabilidades!$N$2:$N$170,MATCH("KJo",Probabilidades!$A$2:$A$170,0)) -> 0.043218675 | D23: =INDEX(Probabilidades!$N$2:$N$170,MATCH("QJo",Probabilidades!$A$2:$A$170,0)) -> 0.043218675 | E23: =INDEX(Probabilidades!$N$2:$N$170,MATCH("JJ",Probabilidades!$A$2:$A$170,0)) -> 0.11361834 | F23: =INDEX(Probabilidades!$N$2:$N$170,MATCH("JTs",Probabilidades!$A$2:$A$170,0)) -> 0.089321112 | G23: =INDEX(Probabilidades!$N$2:$N$170,MATCH("J9s",Probabilidades!$A$2:$A$170,0)) -> 0.089321112 | H23: =INDEX(Probabilidades!$N$2:$N$170,MATCH("J8s",Probabilidades!$A$2:$A$170,0)) -> 0.089321112 | I23: =INDEX(Probabilidades!$N$2:$N$170,MATCH("J7s",Probabilidades!$A$2:$A$170,0)) -> 0.089321112 | J23: =INDEX(Probabilidades!$N$2:$N$170,MATCH("J6s",Probabilidades!$A$2:$A$170,0)) -> 0.089321112 | K23: =INDEX(Probabilidades!$N$2:$N$170,MATCH("J5s",Probabilidades!$A$2:$A$170,0)) -> 0.089321112 | L23: =INDEX(Probabilidades!$N$2:$N$170,MATCH("J4s",Probabilidades!$A$2:$A$170,0)) -> 0.089321112 | M23: =INDEX(Probabilidades!$N$2:$N$170,MATCH("J3s",Probabilidades!$A$2:$A$170,0)) -> 0.089321112 | N23: =INDEX(Probabilidades!$N$2:$N$170,MATCH("J2s",Probabilidades!$A$2:$A$170,0)) -> 0.089321112
A24: T | B24: =INDEX(Probabilidades!$N$2:$N$170,MATCH("ATo",Probabilidades!$A$2:$A$170,0)) -> 0.043218675 | C24: =INDEX(Probabilidades!$N$2:$N$170,MATCH("KTo",Probabilidades!$A$2:$A$170,0)) -> 0.043218675 | D24: =INDEX(Probabilidades!$N$2:$N$170,MATCH("QTo",Probabilidades!$A$2:$A$170,0)) -> 0.043218675 | E24: =INDEX(Probabilidades!$N$2:$N$170,MATCH("JTo",Probabilidades!$A$2:$A$170,0)) -> 0.043218675 | F24: =INDEX(Probabilidades!$N$2:$N$170,MATCH("TT",Probabilidades!$A$2:$A$170,0)) -> 0.11361834 | G24: =INDEX(Probabilidades!$N$2:$N$170,MATCH("T9s",Probabilidades!$A$2:$A$170,0)) -> 0.089321112 | H24: =INDEX(Probabilidades!$N$2:$N$170,MATCH("T8s",Probabilidades!$A$2:$A$170,0)) -> 0.089321112 | I24: =INDEX(Probabilidades!$N$2:$N$170,MATCH("T7s",Probabilidades!$A$2:$A$170,0)) -> 0.089321112 | J24: =INDEX(Probabilidades!$N$2:$N$170,MATCH("T6s",Probabilidades!$A$2:$A$170,0)) -> 0.089321112 | K24: =INDEX(Probabilidades!$N$2:$N$170,MATCH("T5s",Probabilidades!$A$2:$A$170,0)) -> 0.089321112 | L24: =INDEX(Probabilidades!$N$2:$N$170,MATCH("T4s",Probabilidades!$A$2:$A$170,0)) -> 0.089321112 | M24: =INDEX(Probabilidades!$N$2:$N$170,MATCH("T3s",Probabilidades!$A$2:$A$170,0)) -> 0.089321112 | N24: =INDEX(Probabilidades!$N$2:$N$170,MATCH("T2s",Probabilidades!$A$2:$A$170,0)) -> 0.089321112
A25: 9 | B25: =INDEX(Probabilidades!$N$2:$N$170,MATCH("A9o",Probabilidades!$A$2:$A$170,0)) -> 0.043218675 | C25: =INDEX(Probabilidades!$N$2:$N$170,MATCH("K9o",Probabilidades!$A$2:$A$170,0)) -> 0.043218675 | D25: =INDEX(Probabilidades!$N$2:$N$170,MATCH("Q9o",Probabilidades!$A$2:$A$170,0)) -> 0.043218675 | E25: =INDEX(Probabilidades!$N$2:$N$170,MATCH("J9o",Probabilidades!$A$2:$A$170,0)) -> 0.043218675 | F25: =INDEX(Probabilidades!$N$2:$N$170,MATCH("T9o",Probabilidades!$A$2:$A$170,0)) -> 0.043218675 | G25: =INDEX(Probabilidades!$N$2:$N$170,MATCH("99",Probabilidades!$A$2:$A$170,0)) -> 0.11361834 | H25: =INDEX(Probabilidades!$N$2:$N$170,MATCH("98s",Probabilidades!$A$2:$A$170,0)) -> 0.089321112 | I25: =INDEX(Probabilidades!$N$2:$N$170,MATCH("97s",Probabilidades!$A$2:$A$170,0)) -> 0.089321112 | J25: =INDEX(Probabilidades!$N$2:$N$170,MATCH("96s",Probabilidades!$A$2:$A$170,0)) -> 0.089321112 | K25: =INDEX(Probabilidades!$N$2:$N$170,MATCH("95s",Probabilidades!$A$2:$A$170,0)) -> 0.089321112 | L25: =INDEX(Probabilidades!$N$2:$N$170,MATCH("94s",Probabilidades!$A$2:$A$170,0)) -> 0.089321112 | M25: =INDEX(Probabilidades!$N$2:$N$170,MATCH("93s",Probabilidades!$A$2:$A$170,0)) -> 0.089321112 | N25: =INDEX(Probabilidades!$N$2:$N$170,MATCH("92s",Probabilidades!$A$2:$A$170,0)) -> 0.089321112
A26: 8 | B26: =INDEX(Probabilidades!$N$2:$N$170,MATCH("A8o",Probabilidades!$A$2:$A$170,0)) -> 0.043218675 | C26: =INDEX(Probabilidades!$N$2:$N$170,MATCH("K8o",Probabilidades!$A$2:$A$170,0)) -> 0.043218675 | D26: =INDEX(Probabilidades!$N$2:$N$170,MATCH("Q8o",Probabilidades!$A$2:$A$170,0)) -> 0.043218675 | E26: =INDEX(Probabilidades!$N$2:$N$170,MATCH("J8o",Probabilidades!$A$2:$A$170,0)) -> 0.043218675 | F26: =INDEX(Probabilidades!$N$2:$N$170,MATCH("T8o",Probabilidades!$A$2:$A$170,0)) -> 0.043218675 | G26: =INDEX(Probabilidades!$N$2:$N$170,MATCH("98o",Probabilidades!$A$2:$A$170,0)) -> 0.043218675 | H26: =INDEX(Probabilidades!$N$2:$N$170,MATCH("88",Probabilidades!$A$2:$A$170,0)) -> 0.11361834 | I26: =INDEX(Probabilidades!$N$2:$N$170,MATCH("87s",Probabilidades!$A$2:$A$170,0)) -> 0.089321112 | J26: =INDEX(Probabilidades!$N$2:$N$170,MATCH("86s",Probabilidades!$A$2:$A$170,0)) -> 0.089321112 | K26: =INDEX(Probabilidades!$N$2:$N$170,MATCH("85s",Probabilidades!$A$2:$A$170,0)) -> 0.089321112 | L26: =INDEX(Probabilidades!$N$2:$N$170,MATCH("84s",Probabilidades!$A$2:$A$170,0)) -> 0.089321112 | M26: =INDEX(Probabilidades!$N$2:$N$170,MATCH("83s",Probabilidades!$A$2:$A$170,0)) -> 0.089321112 | N26: =INDEX(Probabilidades!$N$2:$N$170,MATCH("82s",Probabilidades!$A$2:$A$170,0)) -> 0.089321112
A27: 7 | B27: =INDEX(Probabilidades!$N$2:$N$170,MATCH("A7o",Probabilidades!$A$2:$A$170,0)) -> 0.043218675 | C27: =INDEX(Probabilidades!$N$2:$N$170,MATCH("K7o",Probabilidades!$A$2:$A$170,0)) -> 0.043218675 | D27: =INDEX(Probabilidades!$N$2:$N$170,MATCH("Q7o",Probabilidades!$A$2:$A$170,0)) -> 0.043218675 | E27: =INDEX(Probabilidades!$N$2:$N$170,MATCH("J7o",Probabilidades!$A$2:$A$170,0)) -> 0.043218675 | F27: =INDEX(Probabilidades!$N$2:$N$170,MATCH("T7o",Probabilidades!$A$2:$A$170,0)) -> 0.043218675 | G27: =INDEX(Probabilidades!$N$2:$N$170,MATCH("97o",Probabilidades!$A$2:$A$170,0)) -> 0.043218675 | H27: =INDEX(Probabilidades!$N$2:$N$170,MATCH("87o",Probabilidades!$A$2:$A$170,0)) -> 0.043218675 | I27: =INDEX(Probabilidades!$N$2:$N$170,MATCH("77",Probabilidades!$A$2:$A$170,0)) -> 0.11361834 | J27: =INDEX(Probabilidades!$N$2:$N$170,MATCH("76s",Probabilidades!$A$2:$A$170,0)) -> 0.089321112 | K27: =INDEX(Probabilidades!$N$2:$N$170,MATCH("75s",Probabilidades!$A$2:$A$170,0)) -> 0.089321112 | L27: =INDEX(Probabilidades!$N$2:$N$170,MATCH("74s",Probabilidades!$A$2:$A$170,0)) -> 0.089321112 | M27: =INDEX(Probabilidades!$N$2:$N$170,MATCH("73s",Probabilidades!$A$2:$A$170,0)) -> 0.089321112 | N27: =INDEX(Probabilidades!$N$2:$N$170,MATCH("72s",Probabilidades!$A$2:$A$170,0)) -> 0.089321112
A28: 6 | B28: =INDEX(Probabilidades!$N$2:$N$170,MATCH("A6o",Probabilidades!$A$2:$A$170,0)) -> 0.043218675 | C28: =INDEX(Probabilidades!$N$2:$N$170,MATCH("K6o",Probabilidades!$A$2:$A$170,0)) -> 0.043218675 | D28: =INDEX(Probabilidades!$N$2:$N$170,MATCH("Q6o",Probabilidades!$A$2:$A$170,0)) -> 0.043218675 | E28: =INDEX(Probabilidades!$N$2:$N$170,MATCH("J6o",Probabilidades!$A$2:$A$170,0)) -> 0.043218675 | F28: =INDEX(Probabilidades!$N$2:$N$170,MATCH("T6o",Probabilidades!$A$2:$A$170,0)) -> 0.043218675 | G28: =INDEX(Probabilidades!$N$2:$N$170,MATCH("96o",Probabilidades!$A$2:$A$170,0)) -> 0.043218675 | H28: =INDEX(Probabilidades!$N$2:$N$170,MATCH("86o",Probabilidades!$A$2:$A$170,0)) -> 0.043218675 | I28: =INDEX(Probabilidades!$N$2:$N$170,MATCH("76o",Probabilidades!$A$2:$A$170,0)) -> 0.043218675 | J28: =INDEX(Probabilidades!$N$2:$N$170,MATCH("66",Probabilidades!$A$2:$A$170,0)) -> 0.11361834 | K28: =INDEX(Probabilidades!$N$2:$N$170,MATCH("65s",Probabilidades!$A$2:$A$170,0)) -> 0.089321112 | L28: =INDEX(Probabilidades!$N$2:$N$170,MATCH("64s",Probabilidades!$A$2:$A$170,0)) -> 0.089321112 | M28: =INDEX(Probabilidades!$N$2:$N$170,MATCH("63s",Probabilidades!$A$2:$A$170,0)) -> 0.089321112 | N28: =INDEX(Probabilidades!$N$2:$N$170,MATCH("62s",Probabilidades!$A$2:$A$170,0)) -> 0.089321112
A29: 5 | B29: =INDEX(Probabilidades!$N$2:$N$170,MATCH("A5o",Probabilidades!$A$2:$A$170,0)) -> 0.043218675 | C29: =INDEX(Probabilidades!$N$2:$N$170,MATCH("K5o",Probabilidades!$A$2:$A$170,0)) -> 0.043218675 | D29: =INDEX(Probabilidades!$N$2:$N$170,MATCH("Q5o",Probabilidades!$A$2:$A$170,0)) -> 0.043218675 | E29: =INDEX(Probabilidades!$N$2:$N$170,MATCH("J5o",Probabilidades!$A$2:$A$170,0)) -> 0.043218675 | F29: =INDEX(Probabilidades!$N$2:$N$170,MATCH("T5o",Probabilidades!$A$2:$A$170,0)) -> 0.043218675 | G29: =INDEX(Probabilidades!$N$2:$N$170,MATCH("95o",Probabilidades!$A$2:$A$170,0)) -> 0.043218675 | H29: =INDEX(Probabilidades!$N$2:$N$170,MATCH("85o",Probabilidades!$A$2:$A$170,0)) -> 0.043218675 | I29: =INDEX(Probabilidades!$N$2:$N$170,MATCH("75o",Probabilidades!$A$2:$A$170,0)) -> 0.043218675 | J29: =INDEX(Probabilidades!$N$2:$N$170,MATCH("65o",Probabilidades!$A$2:$A$170,0)) -> 0.043218675 | K29: =INDEX(Probabilidades!$N$2:$N$170,MATCH("55",Probabilidades!$A$2:$A$170,0)) -> 0.11361834 | L29: =INDEX(Probabilidades!$N$2:$N$170,MATCH("54s",Probabilidades!$A$2:$A$170,0)) -> 0.089321112 | M29: =INDEX(Probabilidades!$N$2:$N$170,MATCH("53s",Probabilidades!$A$2:$A$170,0)) -> 0.089321112 | N29: =INDEX(Probabilidades!$N$2:$N$170,MATCH("52s",Probabilidades!$A$2:$A$170,0)) -> 0.089321112
A30: 4 | B30: =INDEX(Probabilidades!$N$2:$N$170,MATCH("A4o",Probabilidades!$A$2:$A$170,0)) -> 0.043218675 | C30: =INDEX(Probabilidades!$N$2:$N$170,MATCH("K4o",Probabilidades!$A$2:$A$170,0)) -> 0.043218675 | D30: =INDEX(Probabilidades!$N$2:$N$170,MATCH("Q4o",Probabilidades!$A$2:$A$170,0)) -> 0.043218675 | E30: =INDEX(Probabilidades!$N$2:$N$170,MATCH("J4o",Probabilidades!$A$2:$A$170,0)) -> 0.043218675 | F30: =INDEX(Probabilidades!$N$2:$N$170,MATCH("T4o",Probabilidades!$A$2:$A$170,0)) -> 0.043218675 | G30: =INDEX(Probabilidades!$N$2:$N$170,MATCH("94o",Probabilidades!$A$2:$A$170,0)) -> 0.043218675 | H30: =INDEX(Probabilidades!$N$2:$N$170,MATCH("84o",Probabilidades!$A$2:$A$170,0)) -> 0.043218675 | I30: =INDEX(Probabilidades!$N$2:$N$170,MATCH("74o",Probabilidades!$A$2:$A$170,0)) -> 0.043218675 | J30: =INDEX(Probabilidades!$N$2:$N$170,MATCH("64o",Probabilidades!$A$2:$A$170,0)) -> 0.043218675 | K30: =INDEX(Probabilidades!$N$2:$N$170,MATCH("54o",Probabilidades!$A$2:$A$170,0)) -> 0.043218675 | L30: =INDEX(Probabilidades!$N$2:$N$170,MATCH("44",Probabilidades!$A$2:$A$170,0)) -> 0.11361834 | M30: =INDEX(Probabilidades!$N$2:$N$170,MATCH("43s",Probabilidades!$A$2:$A$170,0)) -> 0.089321112 | N30: =INDEX(Probabilidades!$N$2:$N$170,MATCH("42s",Probabilidades!$A$2:$A$170,0)) -> 0.089321112
A31: 3 | B31: =INDEX(Probabilidades!$N$2:$N$170,MATCH("A3o",Probabilidades!$A$2:$A$170,0)) -> 0.043218675 | C31: =INDEX(Probabilidades!$N$2:$N$170,MATCH("K3o",Probabilidades!$A$2:$A$170,0)) -> 0.043218675 | D31: =INDEX(Probabilidades!$N$2:$N$170,MATCH("Q3o",Probabilidades!$A$2:$A$170,0)) -> 0.043218675 | E31: =INDEX(Probabilidades!$N$2:$N$170,MATCH("J3o",Probabilidades!$A$2:$A$170,0)) -> 0.043218675 | F31: =INDEX(Probabilidades!$N$2:$N$170,MATCH("T3o",Probabilidades!$A$2:$A$170,0)) -> 0.043218675 | G31: =INDEX(Probabilidades!$N$2:$N$170,MATCH("93o",Probabilidades!$A$2:$A$170,0)) -> 0.043218675 | H31: =INDEX(Probabilidades!$N$2:$N$170,MATCH("83o",Probabilidades!$A$2:$A$170,0)) -> 0.043218675 | I31: =INDEX(Probabilidades!$N$2:$N$170,MATCH("73o",Probabilidades!$A$2:$A$170,0)) -> 0.043218675 | J31: =INDEX(Probabilidades!$N$2:$N$170,MATCH("63o",Probabilidades!$A$2:$A$170,0)) -> 0.043218675 | K31: =INDEX(Probabilidades!$N$2:$N$170,MATCH("53o",Probabilidades!$A$2:$A$170,0)) -> 0.043218675 | L31: =INDEX(Probabilidades!$N$2:$N$170,MATCH("43o",Probabilidades!$A$2:$A$170,0)) -> 0.043218675 | M31: =INDEX(Probabilidades!$N$2:$N$170,MATCH("33",Probabilidades!$A$2:$A$170,0)) -> 0.11361834 | N31: =INDEX(Probabilidades!$N$2:$N$170,MATCH("32s",Probabilidades!$A$2:$A$170,0)) -> 0.089321112
A32: 2 | B32: =INDEX(Probabilidades!$N$2:$N$170,MATCH("A2o",Probabilidades!$A$2:$A$170,0)) -> 0.043218675 | C32: =INDEX(Probabilidades!$N$2:$N$170,MATCH("K2o",Probabilidades!$A$2:$A$170,0)) -> 0.043218675 | D32: =INDEX(Probabilidades!$N$2:$N$170,MATCH("Q2o",Probabilidades!$A$2:$A$170,0)) -> 0.043218675 | E32: =INDEX(Probabilidades!$N$2:$N$170,MATCH("J2o",Probabilidades!$A$2:$A$170,0)) -> 0.043218675 | F32: =INDEX(Probabilidades!$N$2:$N$170,MATCH("T2o",Probabilidades!$A$2:$A$170,0)) -> 0.043218675 | G32: =INDEX(Probabilidades!$N$2:$N$170,MATCH("92o",Probabilidades!$A$2:$A$170,0)) -> 0.043218675 | H32: =INDEX(Probabilidades!$N$2:$N$170,MATCH("82o",Probabilidades!$A$2:$A$170,0)) -> 0.043218675 | I32: =INDEX(Probabilidades!$N$2:$N$170,MATCH("72o",Probabilidades!$A$2:$A$170,0)) -> 0.043218675 | J32: =INDEX(Probabilidades!$N$2:$N$170,MATCH("62o",Probabilidades!$A$2:$A$170,0)) -> 0.043218675 | K32: =INDEX(Probabilidades!$N$2:$N$170,MATCH("52o",Probabilidades!$A$2:$A$170,0)) -> 0.043218675 | L32: =INDEX(Probabilidades!$N$2:$N$170,MATCH("42o",Probabilidades!$A$2:$A$170,0)) -> 0.043218675 | M32: =INDEX(Probabilidades!$N$2:$N$170,MATCH("32o",Probabilidades!$A$2:$A$170,0)) -> 0.043218675 | N32: =INDEX(Probabilidades!$N$2:$N$170,MATCH("22",Probabilidades!$A$2:$A$170,0)) -> 0.11361834
A35: Tus cartas mejoran la categoría del tablero
B36: A | C36: K | D36: Q | E36: J | F36: T | G36: 9 | H36: 8 | I36: 7 | J36: 6 | K36: 5 | L36: 4 | M36: 3 | N36: 2
A37: A | B37: =INDEX(Probabilidades!$P$2:$P$170,MATCH("AA",Probabilidades!$A$2:$A$170,0)) -> 0.9472229 | C37: =INDEX(Probabilidades!$P$2:$P$170,MATCH("AKs",Probabilidades!$A$2:$A$170,0)) -> 0.54631624 | D37: =INDEX(Probabilidades!$P$2:$P$170,MATCH("AQs",Probabilidades!$A$2:$A$170,0)) -> 0.54923021 | E37: =INDEX(Probabilidades!$P$2:$P$170,MATCH("AJs",Probabilidades!$A$2:$A$170,0)) -> 0.55214418 | F37: =INDEX(Probabilidades!$P$2:$P$170,MATCH("ATs",Probabilidades!$A$2:$A$170,0)) -> 0.55505815 | G37: =INDEX(Probabilidades!$P$2:$P$170,MATCH("A9s",Probabilidades!$A$2:$A$170,0)) -> 0.54390068 | H37: =INDEX(Probabilidades!$P$2:$P$170,MATCH("A8s",Probabilidades!$A$2:$A$170,0)) -> 0.54672497 | I37: =INDEX(Probabilidades!$P$2:$P$170,MATCH("A7s",Probabilidades!$A$2:$A$170,0)) -> 0.54672497 | J37: =INDEX(Probabilidades!$P$2:$P$170,MATCH("A6s",Probabilidades!$A$2:$A$170,0)) -> 0.54390068 | K37: =INDEX(Probabilidades!$P$2:$P$170,MATCH("A5s",Probabilidades!$A$2:$A$170,0)) -> 0.55505815 | L37: =INDEX(Probabilidades!$P$2:$P$170,MATCH("A4s",Probabilidades!$A$2:$A$170,0)) -> 0.55214418 | M37: =INDEX(Probabilidades!$P$2:$P$170,MATCH("A3s",Probabilidades!$A$2:$A$170,0)) -> 0.54923021 | N37: =INDEX(Probabilidades!$P$2:$P$170,MATCH("A2s",Probabilidades!$A$2:$A$170,0)) -> 0.54631624
A38: K | B38: =INDEX(Probabilidades!$P$2:$P$170,MATCH("AKo",Probabilidades!$A$2:$A$170,0)) -> 0.5120344 | C38: =INDEX(Probabilidades!$P$2:$P$170,MATCH("KK",Probabilidades!$A$2:$A$170,0)) -> 0.9472229 | D38: =INDEX(Probabilidades!$P$2:$P$170,MATCH("KQs",Probabilidades!$A$2:$A$170,0)) -> 0.55713106 | E38: =INDEX(Probabilidades!$P$2:$P$170,MATCH("KJs",Probabilidades!$A$2:$A$170,0)) -> 0.56004503 | F38: =INDEX(Probabilidades!$P$2:$P$170,MATCH("KTs",Probabilidades!$A$2:$A$170,0)) -> 0.56295899 | G38: =INDEX(Probabilidades!$P$2:$P$170,MATCH("K9s",Probabilidades!$A$2:$A$170,0)) -> 0.55180153 | H38: =INDEX(Probabilidades!$P$2:$P$170,MATCH("K8s",Probabilidades!$A$2:$A$170,0)) -> 0.54390068 | I38: =INDEX(Probabilidades!$P$2:$P$170,MATCH("K7s",Probabilidades!$A$2:$A$170,0)) -> 0.54672497 | J38: =INDEX(Probabilidades!$P$2:$P$170,MATCH("K6s",Probabilidades!$A$2:$A$170,0)) -> 0.54672497 | K38: =INDEX(Probabilidades!$P$2:$P$170,MATCH("K5s",Probabilidades!$A$2:$A$170,0)) -> 0.5471573 | L38: =INDEX(Probabilidades!$P$2:$P$170,MATCH("K4s",Probabilidades!$A$2:$A$170,0)) -> 0.54424333 | M38: =INDEX(Probabilidades!$P$2:$P$170,MATCH("K3s",Probabilidades!$A$2:$A$170,0)) -> 0.54132936 | N38: =INDEX(Probabilidades!$P$2:$P$170,MATCH("K2s",Probabilidades!$A$2:$A$170,0)) -> 0.53841539
A39: Q | B39: =INDEX(Probabilidades!$P$2:$P$170,MATCH("AQo",Probabilidades!$A$2:$A$170,0)) -> 0.51520182 | C39: =INDEX(Probabilidades!$P$2:$P$170,MATCH("KQo",Probabilidades!$A$2:$A$170,0)) -> 0.52370773 | D39: =INDEX(Probabilidades!$P$2:$P$170,MATCH("QQ",Probabilidades!$A$2:$A$170,0)) -> 0.94745795 | E39: =INDEX(Probabilidades!$P$2:$P$170,MATCH("QJs",Probabilidades!$A$2:$A$170,0)) -> 0.57085984 | F39: =INDEX(Probabilidades!$P$2:$P$170,MATCH("QTs",Probabilidades!$A$2:$A$170,0)) -> 0.57377381 | G39: =INDEX(Probabilidades!$P$2:$P$170,MATCH("Q9s",Probabilidades!$A$2:$A$170,0)) -> 0.56261634 | H39: =INDEX(Probabilidades!$P$2:$P$170,MATCH("Q8s",Probabilidades!$A$2:$A$170,0)) -> 0.55471549 | I39: =INDEX(Probabilidades!$P$2:$P$170,MATCH("Q7s",Probabilidades!$A$2:$A$170,0)) -> 0.54681465 | J39: =INDEX(Probabilidades!$P$2:$P$170,MATCH("Q6s",Probabilidades!$A$2:$A$170,0)) -> 0.54963894 | K39: =INDEX(Probabilidades!$P$2:$P$170,MATCH("Q5s",Probabilidades!$A$2:$A$170,0)) -> 0.55007127 | L39: =INDEX(Probabilidades!$P$2:$P$170,MATCH("Q4s",Probabilidades!$A$2:$A$170,0)) -> 0.5471573 | M39: =INDEX(Probabilidades!$P$2:$P$170,MATCH("Q3s",Probabilidades!$A$2:$A$170,0)) -> 0.54424333 | N39: =INDEX(Probabilidades!$P$2:$P$170,MATCH("Q2s",Probabilidades!$A$2:$A$170,0)) -> 0.54132936
A40: J | B40: =INDEX(Probabilidades!$P$2:$P$170,MATCH("AJo",Probabilidades!$A$2:$A$170,0)) -> 0.51836923 | C40: =INDEX(Probabilidades!$P$2:$P$170,MATCH("KJo",Probabilidades!$A$2:$A$170,0)) -> 0.52687515 | D40: =INDEX(Probabilidades!$P$2:$P$170,MATCH("QJo",Probabilidades!$A$2:$A$170,0)) -> 0.53854849 | E40: =INDEX(Probabilidades!$P$2:$P$170,MATCH("JJ",Probabilidades!$A$2:$A$170,0)) -> 0.94769299 | F40: =INDEX(Probabilidades!$P$2:$P$170,MATCH("JTs",Probabilidades!$A$2:$A$170,0)) -> 0.58458863 | G40: =INDEX(Probabilidades!$P$2:$P$170,MATCH("J9s",Probabilidades!$A$2:$A$170,0)) -> 0.57343116 | H40: =INDEX(Probabilidades!$P$2:$P$170,MATCH("J8s",Probabilidades!$A$2:$A$170,0)) -> 0.56553031 | I40: =INDEX(Probabilidades!$P$2:$P$170,MATCH("J7s",Probabilidades!$A$2:$A$170,0)) -> 0.55762946 | J40: =INDEX(Probabilidades!$P$2:$P$170,MATCH("J6s",Probabilidades!$A$2:$A$170,0)) -> 0.54972861 | K40: =INDEX(Probabilidades!$P$2:$P$170,MATCH("J5s",Probabilidades!$A$2:$A$170,0)) -> 0.55298524 | L40: =INDEX(Probabilidades!$P$2:$P$170,MATCH("J4s",Probabilidades!$A$2:$A$170,0)) -> 0.55007127 | M40: =INDEX(Probabilidades!$P$2:$P$170,MATCH("J3s",Probabilidades!$A$2:$A$170,0)) -> 0.5471573 | N40: =INDEX(Probabilidades!$P$2:$P$170,MATCH("J2s",Probabilidades!$A$2:$A$170,0)) -> 0.54424333
A41: T | B41: =INDEX(Probabilidades!$P$2:$P$170,MATCH("ATo",Probabilidades!$A$2:$A$170,0)) -> 0.52153665 | C41: =INDEX(Probabilidades!$P$2:$P$170,MATCH("KTo",Probabilidades!$A$2:$A$170,0)) -> 0.53004257 | D41: =INDEX(Probabilidades!$P$2:$P$170,MATCH("QTo",Probabilidades!$A$2:$A$170,0)) -> 0.54171591 | E41: =INDEX(Probabilidades!$P$2:$P$170,MATCH("JTo",Probabilidades!$A$2:$A$170,0)) -> 0.55338925 | F41: =INDEX(Probabilidades!$P$2:$P$170,MATCH("TT",Probabilidades!$A$2:$A$170,0)) -> 0.94792803 | G41: =INDEX(Probabilidades!$P$2:$P$170,MATCH("T9s",Probabilidades!$A$2:$A$170,0)) -> 0.58424597 | H41: =INDEX(Probabilidades!$P$2:$P$170,MATCH("T8s",Probabilidades!$A$2:$A$170,0)) -> 0.57634513 | I41: =INDEX(Probabilidades!$P$2:$P$170,MATCH("T7s",Probabilidades!$A$2:$A$170,0)) -> 0.56844428 | J41: =INDEX(Probabilidades!$P$2:$P$170,MATCH("T6s",Probabilidades!$A$2:$A$170,0)) -> 0.56054343 | K41: =INDEX(Probabilidades!$P$2:$P$170,MATCH("T5s",Probabilidades!$A$2:$A$170,0)) -> 0.55307491 | L41: =INDEX(Probabilidades!$P$2:$P$170,MATCH("T4s",Probabilidades!$A$2:$A$170,0)) -> 0.55298524 | M41: =INDEX(Probabilidades!$P$2:$P$170,MATCH("T3s",Probabilidades!$A$2:$A$170,0)) -> 0.55007127 | N41: =INDEX(Probabilidades!$P$2:$P$170,MATCH("T2s",Probabilidades!$A$2:$A$170,0)) -> 0.5471573
A42: 9 | B42: =INDEX(Probabilidades!$P$2:$P$170,MATCH("A9o",Probabilidades!$A$2:$A$170,0)) -> 0.50951311 | C42: =INDEX(Probabilidades!$P$2:$P$170,MATCH("K9o",Probabilidades!$A$2:$A$170,0)) -> 0.51801903 | D42: =INDEX(Probabilidades!$P$2:$P$170,MATCH("Q9o",Probabilidades!$A$2:$A$170,0)) -> 0.52969237 | E42: =INDEX(Probabilidades!$P$2:$P$170,MATCH("J9o",Probabilidades!$A$2:$A$170,0)) -> 0.5413657 | F42: =INDEX(Probabilidades!$P$2:$P$170,MATCH("T9o",Probabilidades!$A$2:$A$170,0)) -> 0.55303904 | G42: =INDEX(Probabilidades!$P$2:$P$170,MATCH("99",Probabilidades!$A$2:$A$170,0)) -> 0.94792709 | H42: =INDEX(Probabilidades!$P$2:$P$170,MATCH("98s",Probabilidades!$A$2:$A$170,0)) -> 0.58381365 | I42: =INDEX(Probabilidades!$P$2:$P$170,MATCH("97s",Probabilidades!$A$2:$A$170,0)) -> 0.5759128 | J42: =INDEX(Probabilidades!$P$2:$P$170,MATCH("96s",Probabilidades!$A$2:$A$170,0)) -> 0.56801195 | K42: =INDEX(Probabilidades!$P$2:$P$170,MATCH("95s",Probabilidades!$A$2:$A$170,0)) -> 0.56054343 | L42: =INDEX(Probabilidades!$P$2:$P$170,MATCH("94s",Probabilidades!$A$2:$A$170,0)) -> 0.54972861 | M42: =INDEX(Probabilidades!$P$2:$P$170,MATCH("93s",Probabilidades!$A$2:$A$170,0)) -> 0.54963894 | N42: =INDEX(Probabilidades!$P$2:$P$170,MATCH("92s",Probabilidades!$A$2:$A$170,0)) -> 0.54672497
A43: 8 | B43: =INDEX(Probabilidades!$P$2:$P$170,MATCH("A8o",Probabilidades!$A$2:$A$170,0)) -> 0.51256301 | C43: =INDEX(Probabilidades!$P$2:$P$170,MATCH("K8o",Probabilidades!$A$2:$A$170,0)) -> 0.50951311 | D43: =INDEX(Probabilidades!$P$2:$P$170,MATCH("Q8o",Probabilidades!$A$2:$A$170,0)) -> 0.52118645 | E43: =INDEX(Probabilidades!$P$2:$P$170,MATCH("J8o",Probabilidades!$A$2:$A$170,0)) -> 0.53285979 | F43: =INDEX(Probabilidades!$P$2:$P$170,MATCH("T8o",Probabilidades!$A$2:$A$170,0)) -> 0.54453312 | G43: =INDEX(Probabilidades!$P$2:$P$170,MATCH("98o",Probabilidades!$A$2:$A$170,0)) -> 0.55257132 | H43: =INDEX(Probabilidades!$P$2:$P$170,MATCH("88",Probabilidades!$A$2:$A$170,0)) -> 0.94792709 | I43: =INDEX(Probabilidades!$P$2:$P$170,MATCH("87s",Probabilidades!$A$2:$A$170,0)) -> 0.58381365 | J43: =INDEX(Probabilidades!$P$2:$P$170,MATCH("86s",Probabilidades!$A$2:$A$170,0)) -> 0.5759128 | K43: =INDEX(Probabilidades!$P$2:$P$170,MATCH("85s",Probabilidades!$A$2:$A$170,0)) -> 0.56844428 | L43: =INDEX(Probabilidades!$P$2:$P$170,MATCH("84s",Probabilidades!$A$2:$A$170,0)) -> 0.55762946 | M43: =INDEX(Probabilidades!$P$2:$P$170,MATCH("83s",Probabilidades!$A$2:$A$170,0)) -> 0.54681465 | N43: =INDEX(Probabilidades!$P$2:$P$170,MATCH("82s",Probabilidades!$A$2:$A$170,0)) -> 0.54672497
A44: 7 | B44: =INDEX(Probabilidades!$P$2:$P$170,MATCH("A7o",Probabilidades!$A$2:$A$170,0)) -> 0.51256301 | C44: =INDEX(Probabilidades!$P$2:$P$170,MATCH("K7o",Probabilidades!$A$2:$A$170,0)) -> 0.51256301 | D44: =INDEX(Probabilidades!$P$2:$P$170,MATCH("Q7o",Probabilidades!$A$2:$A$170,0)) -> 0.51268053 | E44: =INDEX(Probabilidades!$P$2:$P$170,MATCH("J7o",Probabilidades!$A$2:$A$170,0)) -> 0.52435387 | F44: =INDEX(Probabilidades!$P$2:$P$170,MATCH("T7o",Probabilidades!$A$2:$A$170,0)) -> 0.5360272 | G44: =INDEX(Probabilidades!$P$2:$P$170,MATCH("97o",Probabilidades!$A$2:$A$170,0)) -> 0.5440654 | H44: =INDEX(Probabilidades!$P$2:$P$170,MATCH("87o",Probabilidades!$A$2:$A$170,0)) -> 0.55257132 | I44: =INDEX(Probabilidades!$P$2:$P$170,MATCH("77",Probabilidades!$A$2:$A$170,0)) -> 0.94792709 | J44: =INDEX(Probabilidades!$P$2:$P$170,MATCH("76s",Probabilidades!$A$2:$A$170,0)) -> 0.58381365 | K44: =INDEX(Probabilidades!$P$2:$P$170,MATCH("75s",Probabilidades!$A$2:$A$170,0)) -> 0.57634513 | L44: =INDEX(Probabilidades!$P$2:$P$170,MATCH("74s",Probabilidades!$A$2:$A$170,0)) -> 0.56553031 | M44: =INDEX(Probabilidades!$P$2:$P$170,MATCH("73s",Probabilidades!$A$2:$A$170,0)) -> 0.55471549 | N44: =INDEX(Probabilidades!$P$2:$P$170,MATCH("72s",Probabilidades!$A$2:$A$170,0)) -> 0.54390068
...

Sheet Validación
A1: Categoría | B1: Promedio ponderado (esta hoja) | C1: Frecuencia clásica 7 cartas | D1: Manos de 7 cartas (conteo clásico) | E1: Diferencia
A2: Carta alta | B2: =SUMPRODUCT(Probabilidades!$C$2:$C$170,Probabilidades!D$2:D$170)/SUM(Probabilidades!$C$2:$C$170) -> 0.1741192 | C2: =D2/$D$12 -> 0.1741192 | D2: 23294460 | E2: =B2-C2 -> 0
A3: Pareja | B3: =SUMPRODUCT(Probabilidades!$C$2:$C$170,Probabilidades!E$2:E$170)/SUM(Probabilidades!$C$2:$C$170) -> 0.43822546 | C3: =D3/$D$12 -> 0.43822546 | D3: 58627800 | E3: =B3-C3 -> 0
A4: Doble pareja | B4: =SUMPRODUCT(Probabilidades!$C$2:$C$170,Probabilidades!F$2:F$170)/SUM(Probabilidades!$C$2:$C$170) -> 0.23495536 | C4: =D4/$D$12 -> 0.23495536 | D4: 31433400 | E4: =B4-C4 -> 0
A5: Trío | B5: =SUMPRODUCT(Probabilidades!$C$2:$C$170,Probabilidades!G$2:G$170)/SUM(Probabilidades!$C$2:$C$170) -> 0.048298698 | C5: =D5/$D$12 -> 0.048298698 | D5: 6461620 | E5: =B5-C5 -> 0
A6: Escalera | B6: =SUMPRODUCT(Probabilidades!$C$2:$C$170,Probabilidades!H$2:H$170)/SUM(Probabilidades!$C$2:$C$170) -> 0.046193821 | C6: =D6/$D$12 -> 0.046193821 | D6: 6180020 | E6: =B6-C6 -> 0
A7: Color | B7: =SUMPRODUCT(Probabilidades!$C$2:$C$170,Probabilidades!I$2:I$170)/SUM(Probabilidades!$C$2:$C$170) -> 0.030254941 | C7: =D7/$D$12 -> 0.030254941 | D7: 4047644 | E7: =B7-C7 -> 0
A8: Full house | B8: =SUMPRODUCT(Probabilidades!$C$2:$C$170,Probabilidades!J$2:J$170)/SUM(Probabilidades!$C$2:$C$170) -> 0.025961023 | C8: =D8/$D$12 -> 0.025961023 | D8: 3473184 | E8: =B8-C8 -> 0
A9: Póker | B9: =SUMPRODUCT(Probabilidades!$C$2:$C$170,Probabilidades!K$2:K$170)/SUM(Probabilidades!$C$2:$C$170) -> 0.0016806723 | C9: =D9/$D$12 -> 0.0016806723 | D9: 224848 | E9: =B9-C9 -> 0
A10: Escalera de color | B10: =SUMPRODUCT(Probabilidades!$C$2:$C$170,Probabilidades!L$2:L$170)/SUM(Probabilidades!$C$2:$C$170) -> 0.0003108281 | C10: =D10/$D$12 -> 0.0003108281 | D10: 41584 | E10: =B10-C10 -> 0
A12: Total de manos de 7 cartas | D12: =SUM(D2:D10) -> 133784560
A14: Fuente de la columna D: conteo clásico de manos de 7 cartas (133.784.560 en total; la escalera de color incluye la escalera real). El programa además comprobó la igualdad exacta con enteros.
